---
title: es6系列-Promise
date: 2020-07-09 10:42:56
tags:
  - 日积月累
  - es6

---

[Noney Li]: https://github.com/noney/ "noneyli"

*—— 同时发表于[coding](http://0kv30q.coding-pages.com/)*

__作者：[Noney Li]__

#### 写在前面

Promise是一种异步解决方案。它是一个构造函数，提供统一的`API`，它包含三种状态分别是`pending（进行中）、fulfilled（已成功）、rejected（已失败）（下面用成功、失败来代码这两种状态）`，它包含以下特点：

+ 状态不受外界影响。只有异步操作能决定它的状态
+ 状态改变之后，就不会再变。此时执行回调，就会立即得到结果（事件的特点是，你错过它，再去监听，就不会得到结果）

它的缺点：

- 无法取消。一旦执行，就无法取消
- 如果没有回调函数，`Promise`抛出的错误，不会冒泡到外部（浏览器会输出错误，并不会中止程序的执行）
- 无法知道中间状态。

<!-- more -->

#### 基本用法

`Promise`是一个构造函数，它接收一个`函数`做为参数，`函数`还有两个参数，分别为`resolve、reject`，它们由`Javscript`引擎提供

- `resolve`作用，在异步操作成功时执行，将状态从`pending（进行中）变成 fulfilled（已成功）`，同时将异步执行的结果作为参数
- `reject`作用，在异步操作失败时执行，将状态从`pending（进行中）变成 rejected（已失败）`，同时将异步执行产生的错误作为参数

```javascript
const promise = new Promise(function(resolve, reject) {
  // ... some code

  if (/* 异步操作成功 */){
    resolve(value);
  } else {
    reject(error);
  }
});
```

```javascript
const pro = new Promise((resolve, reject) => {
  console.log('start');
  setTimeout(() => {
    console.log('top');
    resolve();
    console.log('bottom');
  }, 1000)
  console.log('end');
})

console.log('lalala');

pro
  .then((data) => {
    console.log('callback');
  })
```

上面的执行结果是：

> start
> end
> lalala
> top
> bottom
> callback

我们从结果可以看出

- Promise 新建后就会`立即执行`，此时是`同步执行`
- resolve函数执行完并`没有结束`，还会接着执行，如果不需要下面的执行，可以`return resolve()`
- then方法会在当前脚本所有`同步任务`执行完之后才会执行，所以我们才在最后看出输出`callback`

#### 实例方法then

`then`方法定义在`Promise.prototype`上，是一个实例方法。当`Promise`状态改变时，就会执行它。它包含两个参数（都是函数），当`Promise`的状态变为`成功`时，就会执行第一个函数，当`Promise`状态变为`失败`时，就会执行它的第二个函数。执行返回的结果分别为`resolve, reject`函数的返回。

```javascript
const pro = new Promise((resolve, reject) => {
  setTimeout(() => {
    resolve(`结果为: 1`);
  }, 1000)
})

pro
  .then((res) => {
    console.log(res);
  })
//结果为: 1
```

```javascript
const pro = new Promise((resolve, reject) => {
  setTimeout(() => {
    reject('报错了~');
  }, 1000)
})

pro
  .then((res) => {
    console.log(res);
  }, (err) =>{
    console.log(err);
  })
//报错了~
```

`then`方法返回的是一个`新的Promise`，它的参数为`then`的返回结果

```javascript
const pro = new Promise((resolve, reject) => {
  setTimeout(() => {
    resolve('结果为: 1');
  }, 1000)
})

pro
  .then((res) => {
    console.log(res);
    return '结果为: 2';
  })
  .then((res) => {
    console.log(res);
  })
//结果为: 1
//结果为: 2
```

当`then`的返回结果为一个`Promise`，`then`方法返回的就是这个`Promise`，此时下一个`then`方法就会等待这个`Promise`的执行结果，它的状态也由这个`Promise`决定。

```javascript
const pro1 = new Promise((resolve, reject) => {
  setTimeout(() => {
    resolve('结果为: 1');
  }, 1000)
})

const pro2 = new Promise((resolve, reject) => {
  setTimeout(() => {
    resolve('结果为: 2');
  }, 1000)
})

pro1
  .then((res) => {
    console.log(res);
    return pro2;
  })
  .then((res) => {
    console.log(res);
  })
//结果为: 1
//结果为: 2
```

```javascript
const pro1 = new Promise((resolve, reject) => {
  setTimeout(() => {
    resolve('结果为: 1');
  }, 1000)
})

const pro2 = new Promise((resolve, reject) => {
  setTimeout(() => {
    reject('报错了~');
  }, 1000)
})

pro1
  .then((res) => {
    console.log(res);
    return pro2;
  })
  .then((res) => {
    console.log(res);
  }, (err) => {
    console.log(err);
  })
//结果为: 1
//报错了~
```

#### 实例方法catch

`catch`方法定义在`Promise.prototype`上，是一个实例方法。是`.then(null, rejection)`或`.then(undefined, rejection)`的别名，用于指定发生错误时的回调函数。

```javascript
const pro = new Promise((resolve, reject) => {
  setTimeout(() => {
    reject('出错了~');
  }, 1000)
})

pro
  .catch((err) => {
    console.log(err);
  })
//出错了~
```

`then`方法执行出错，也会被`catch`捕获。

```javascript
const pro = new Promise((resolve, reject) => {
  setTimeout(() => {
    resolve('结果为: 1');
  }, 1000)
})

pro
  .then((res) => {
    console.log(res);
    return x;
  })
  .catch((err) => {
    console.log(err);
  })
//结果为: 1
//ReferenceError: x is not defined
//    at /Users/linoney/noney/node/testPromise/test.js:10:3
```

`reject`方法，等同于抛出错误。

```javascript
const pro = new Promise((resolve, reject) => {
  throw new Error('出错误~');
})

pro
  .catch((err) => {
    console.log(err);
  })

const pro1 = new Promise((resolve, reject) => {
  try {
    new Error('出错了~');
  } catch(err) {
    reject(err);
  }
})

pro1
  .catch((err) => {
    console.log(err);
  })

const pro2 = new Promise((resolve, reject) => {
  reject(new Error('出错了~'));
})

pro2
  .catch((err) => {
    console.log(err);
  })
```

当`Promise`状态变为`成功`后，再抛出错误无效

```javascript
const pro = new Promise((resolve, reject) => {
  resolve('结果为: 1');
  throw new Error('出错误~');
})

pro
  .catch((err) => {
    console.log(err);
  })
//不会有任何输出
```

`Promise`错误会冒泡，直到被捕获（总是被下一个`catch`捕获）

```javascript
const pro = new Promise((resolve, reject) => {
  resolve('结果为: 1');
})

pro
  .then((res) => {
    console.log(res);
  })
  .then((res) => {
    throw new Error('这里出错了~');
  })
  .then((res) => {
    console.log(2);
  })
  .catch((err) => {
    console.log(err);
  })
//结果为: 1
//Error: 这里出错了~
//    at /Users/linoney/noney/node/testPromise/test.js:10:9
```

***注意：*** 尽量使用`catch`方式捕获错误，不要使用第二个参数函数来捕获错误。因为`catch`还可以捕获`then`函数的错误。

```javascript
const pro = new Promise((resolve, reject) => {
  resolve('结果为: 1');
})

pro
  .then((res) => {
    console.log(x);
  })
  .catch((err) => {
    console.log(err);
  })
//结果为: 1
//ReferenceError: x is not defined
//    at /Users/linoney/noney/node/testPromise/test.js:7:15
pro
  .then((res) => {
    console.log(x);
  }, (err) => {
    console.log(err);
  })
//无法捕获到错误

```

`Promise`会'吃掉'错误，它内部执行出错不会抛出到外面，如果我们不用`catch`方法捕获，浏览器也不会帮我们处理错误（只会有提示，不会中止程序执行）

```javascript
console.log(x)
//程序已中断，不会继续执行
setTimeout(() => {
  console.log('继续执行~');
}, 0)
```

```javascript
const pro = new Promise((resolve, reject) => {
  resolve(x);
});

pro
  .then((res) => {
    console.log(res);
  })
//继续执行，程序不会中断
setTimeout(() => {
  console.log('继续执行~');
}, 0)
//继续执行~
```

`Promise`状态完成时，再抛出的错误会冒泡到外层。

```javascript
const pro = new Promise((resolve, reject) => {
  resolve(`结果为: 1`);
  setTimeout(() => {
    console.log(x);
  }, 0)
});

pro
  .then((res) => {
    console.log(res);
  })
```

如果最后一个`catch`方法中抛出一个错误，因为后面没有`catch`方法了，所以这个错误不会被捕获，也不会传递到外层。

#### 实例方法finally

无论`Promise`是什么状态，最后都会执行`finally`方法。

```javascript
const pro = new Promise((resolve, reject) => {
  resolve(`结果为: 1`);
})

pro
  .then((res) => {
    console.log(res);
    return res;
  })
  .catch((err) => {
    console.log(err);
  })
  .finally(() => {
    console.log('最后执行~');
  })
//结果为: 1
//最后执行~
```

#### 静态方法all

`Promise.all`的参数为一个数组（可以不是数组，但必须具有`Iterator` 接口，且返回的每个成员都是`Promise`实例。），数组的每一项都是一个`Promise`实例，如果不是，它会调用`Promise.reslove`方法转换成`Promise`实例，`Promise.all`的返回值为一个`Promise`实例。

- `所有`参数实例状态为`成功`，包装实例的状态为`成功`

```javascript
const pro1 = new Promise((resolve, reject) => {
  resolve(`结果为: 1`);
})

const pro2 = new Promise((resolve, reject) => {
  resolve(`结果为: 2`);
})

const pro3 = new Promise((resolve, reject) => {
  resolve(`结果为: 3`);
})

Promise.all([pro1, pro2, pro3])
  .then((res) => {
    console.log(res);
  })
// [ '结果为: 1', '结果为: 2', '结果为: 3' ]
```

- 其中`一个`参数实例状态为`失败`，包装实例的状态为`失败`

```javascript
const pro1 = new Promise((resolve, reject) => {
  resolve(`结果为: 1`);
})

const pro2 = new Promise((resolve, reject) => {
  reject(`报错了`);
})

const pro3 = new Promise((resolve, reject) => {
  resolve(`结果为: 3`);
})

Promise.all([pro1, pro2, pro3])
  .then((res) => {
    console.log(res);
  })
  .catch((err) => {
    console.log(err);
  })
//报错了
```

当本身的异步操作完成，才会执行`Promise.all`的回调函数

```javascript
const pro1 = new Promise((resolve, reject) => {
  resolve(`结果为: 1`);
})

const pro2 = new Promise((resolve, reject) => {
  resolve(`结果为: 2`);
})

const pro3 = new Promise((resolve, reject) => {
  resolve(`结果为: 3`);
})

pro1
  .then((res) => console.log(1))

pro2
  .then((res) => console.log(2))

Promise.all([pro1, pro2, pro3])
  .then((res) => {
    console.log(res);
  })
  .catch((err) => {
    console.log(err);
  })
//1
//2
//[ '结果为: 1', '结果为: 2', '结果为: 3' ]
```

所有实例都注册了自己的`catch`方法，此时不会触发`Promise.all`的`catch`方法，并且会触发`Promise.all`的`then`方法（因为实例自己的`catch`方法，会返回一个新的`Promise`实例，此时新的实例的状态为`成功`）

```javascript
let pro1 = new Promise((resolve, reject) => {
  resolve(`结果为: 1`);
});

let pro2 = new Promise((resolve, reject) => {
  reject(`出错了~`);
});

let pro3 = new Promise((resolve, reject) => {
  resolve(`结果为: 3`);
});

pro1 = pro1
  .then((res) => res)
  .catch((err) => err);

pro2 = pro2
  .then((res) => res)
  .catch((err) => err);

pro3 = pro3
  .then((res) => res)
  .catch((err) => err)

Promise.all([pro1, pro2])
  .then((res) => {
    console.log(res);
  })
  .catch((err) => {
    console.log(err, 7);
  })
//[ '结果为: 1', '出错了~' ]
```

#### 静态方法race

`Promise.race`方法，用法和`Promise.all`方法一样，不同的是

- 只要有一个实例状态改变，包装实例状态就会改变，率先改变状态的实例的返回值，做为返回参数。

```javascript
let pro = new Promise((resolve, reject) => {
  setTimeout(() => {
    resolve(`结果为: 1`);
  }, 3000)
});

let pro1 = new Promise((resolve, reject) => {
  setTimeout(() => {
    resolve(`结果为: 2`);
  }, 2000)
});

Promise.race([pro, pro1])
  .then((res) => {
    console.log(res);
  })
  .catch((err) => {
    console.log(err, 7);
  })
//结果为: 2
```

#### 静态方法allSettled

`Promise.allSettled`方法，用法和`Promise.all`方法一样，不同的是

- 所有实例状态都改变，不管是`成功`还是`失败`，包装实例状态都是`成功`
- 返回值是一个数组，数组的每个成员都是一个对象

```javascript
const pro = new Promise((resolve, reject) => {
  setTimeout(() => {
    resolve('结果为: 1');
  }, 1000)
})

const pro1 = new Promise((resolve, reject) => {
  setTimeout(() => {
    reject('出错了~');
  }, 2000)
})

Promise.allSettled([pro, pro1])
  .then((data) => {
    console.log(data);
  })
/*[
  { status: 'fulfilled', value: '结果为: 1' },
  { status: 'rejected', reason: '出错了~' }
]*/
```

#### 静态方法any

`Promise.any`方法，和`Promise.all`相反。

- 只要有一个实例状态变成`成功`，包装实例状态就会变成`成功`
- 所有实例状态变成`失败`，包装实例状态就会变成`失败`，它抛出的错误是一个`AggregateError`实例，是一个数组，每个成员对于一个错误

```javascript
const pro = new Promise((resolve, reject) => {
  setTimeout(() => {
    resolve('结果为: 1');
  }, 1000)
})

const pro1 = new Promise((resolve, reject) => {
  setTimeout(() => {
    reject('出错了~');
  }, 2000)
})

const pro2 = new Promise((resolve, reject) => {
  setTimeout(() => {
    reject('出错了~');
  }, 2000)
})

Promise.any([pro, pro1, pro2])
  .then((data) => {
    console.log(data);
  })
//结果为: 1
Promise.any([pro1, pro2])
  .then((data) => {
    console.log(data);
  })
//[出错了~, 出错了~]
```

#### 静态方法resolve

`Promise.resolve`，可以将现有对象转为`Promise`对象。

```javascript
Promise.resolve('foo')
// 等价于
new Promise(resolve => resolve('foo'))
```

参数分为四种情况

- 参数是一个`Promise`实例，直接返回

```javascript
const pro = new Promise((resolve, reject) => {
  setTimeout(() => {
    resolve('结果为: 1');
  }, 1000)
})

Promise.resolve(pro)
  .then((res) => {
    console.log(res);
  })
//结果为: 1
```

- 参数为一个`thenable`对象（包含`then`方法的对象），转为`Promise`对象，并立即执行它的`then`方法

```javascript
const thenObj = {
  then(resolve, reject) {
    resolve(1);
  }
}
//立即执行thenObj.then，此时pro的状态为resolve，然后执行prp.then
let pro = Promise.resolve(thenObj)
pro
  .then((res) => {
    console.log(res);
  })
//1
```

- 参数是原始值或者是一个不具有`then`方法的对象，转为`Promise`对象，状态为`resolve`

```javascript
Promise.resolve('hi')
  .then((res) => {
    console.log(res);
  })
//hi
```

- 无参数时，直接返回一个`Promise`，状态为`resolve`

```javascript
Promise.resolve()
  .then(() => {
    
  })
```

***注意：***立即`resolve`的`Promise`对象，是在本轮“事件循环”（event loop）的结束时执行，而不是在下一轮“事件循环”的开始时。

```javascript
// 在下一轮“事件循环”开始时执行
setTimeout(function () {
  console.log('three');
}, 0);
// 立即resolve()在本轮“事件循环”结束时执行
Promise.resolve().then(function () {
  console.log('two');
});
// 同步执行
console.log('one');

// one
// two
// three
```

#### 静态方法reject

`Promise.reject`，返回一个`Promise`对象，状态为`reject`。

```javascript
const p = Promise.reject('出错了');
// 等同于
const p = new Promise((resolve, reject) => reject('出错了'))

p.then(null, function (s) {
  console.log(s)
});
// 出错了
```

***注意：***`Promise.reject()`方法的参数，会原封不动地返回，变成后续方法的参数。这一点与`Promise.resolve`方法不一致。

```javascript
const thenable = {
  then(resolve, reject) {
  	reject('出错了');
  }
};

Promise.reject(thenable)
.catch(e => {
  console.log(e === thenable)
})
// true
```

上面代码中，`Promise.reject`方法的参数是一个`thenable`对象，执行以后，后面`catch`方法的参数不是`reject`抛出的“出错了”这个字符串，而是`thenable`对象。

#### 总结

| 方法       | 实例对象成员状态 | 包装实例状态   | 返回值                                | 备注                                 |
| ---------- | ---------------- | -------------- | ------------------------------------- | ------------------------------------ |
| all        | `一个失败`       | `失败`         | 率先变成`失败`的 Promise 实例的返回值 | 有一个失败就结束                     |
| all        | `所有成功`       | `成功`         | 所有 Promise 实例的返回值组成的`数组` | 所有成功才结束                       |
| allSeetled | `所有成功或失败` | `成功`         | 所有 Promise 实例的返回值组成的`数组` | 所有执行完成才结束，不管成功还是失败 |
| race       | `一个成功或失败` | `成功`或`失败` | 率先改变的 Promise 实例的返回值       | 一个执行完成就结束，不管成功还是失败 |
| any        | `一个成功`       | `成功`         | 率先变成`成功`的 Promise 实例的返回值 | 一个成功就结束                       |
| any        | `所有失败`       | `失败`         | 所有 Promise 实例的返回值组成的`数组` | 所有失败才结束                       |

#### 参考

[Promise 对象](https://es6.ruanyifeng.com/#docs/promise#Promise-race)