---
layout: es6
title: Promise对象
date: 2022-03-23 14:32:16
tags:
---

[Noney Li]: https://github.com/noney/ "noneyli"

*—— 同时发表于[coding](http://0kv30q.coding-pages.com/)*

__作者：[Noney Li]__

#### 写在前面
`Promise`是异步编程的一种解决方案，比传统的解决方案**回调函数和事件**。有了它，我们可以用同步的方式表达异步操作，避免`回调地狱`。

#### 特点
- 它就是一个容器，内部的状态不受外界影响。
  > 三种状态分别是`pending`（进行时）、`fulfilled`（已成功）、`rejected`（已失败），只有异常操作的结果才能改变它们
- 状态一旦改变，将不会再变。
  > 状态改变后，再对`promise`添加回调函数，也会立即得到这个结果。与`Event`不同，如果你错过了事件，再去监听，将无法再得到结果

#### 缺点
- 无法取消，一旦新建会**立即执行**，无法中途取消
- 如果不设置回调函数，内部抛出的错误，将无法反应到外部
- 处于`pending`状态时，无法感知运行进度

#### 构造函数
`Promise`接收一个函数作为参数，该函数有`resolve、reject`两个参数，也均为函数，这两个参数由`引擎`提供。
- `resolve`函数，是将`Promise`的状态由`pending`改变成`fulfilled`。同时将异步操作的结果作为`参数`传递出去
- `reject`函数，是将`Promise`的状态由`pending`改变成`rejected`。同时将异步操作失败的`错误`传出去
```javascript
  new Promise(function(resolve, reject) {
    if (/* 异常执行成功 */) {
      resolve(data);
    } else {
      reject(err);
    }
  });
```
**注意：**
- 调用`resolve`方法后，`Promise`还会继续执行，最好添加`return`，将后面的操作放在`then`回调里面
```javascript
// 无return
new Promise(function(resolve, reject) {
  setTimeout(() => {
    resolve('success');
    console.log(1);
  }, 1000);
});
// 1

// 有return
new Promise(function(resolve, reject) {
  setTimeout(() => {
    return resolve('success');
    console.log(1);
  }, 1000);
});
```
- 新建`Promise会立即执行，为`同步运行`
```javascript
console.log(3);
new Promise(function(resolve, reject) {
  console.log(2);
  setTimeout(() => {
    console.log(1);
    return resolve('success');
  }, 1000);
});
console.log(4);
// 3 2 4 1
```

### 实例方法then
`then`为`Promise`状态改变时的回调函数，它接收两个参数（都是可选的），均为函数。
- **参数一** 状态由`pending`改变成`fulfilled`的回调函数，参数为`resolve`函数传递的值
```javascript
const pro = new Promise(function(resolve, reject) {
  setTimeout(() => {
    resolve('success');
  }, 1000);
});
pro
  .then((data) => {
    console.log(data); // success
  })
```
- **参数二** 状态由`pending`改变成`rejected`，参数为`reject`函数传递的值
```javascript
const pro = new Promise(function(resolve, reject) {
  setTimeout(() => {
    reject('error');
  }, 1000);
});
pro
  .then(null, (err) => {
    console.log(err); // error
  })
```
- **返回值** 为一个新的`Promise`实例，因此可以采用链式写法。下一个`then`函数的参数为新的`Promise`实例的`resolve`执行结果。
> 当返回值不为`Promise`时，引擎将会调用`Promise.resolve`方法，将参数传递下去

```javascript
const pro = new Promise(function(resolve, reject) {
  setTimeout(() => {
    resolve('success');
  }, 1000);
});
pro
  .then((data) => {
    console.log(data);
    return 'promise';
  })
  .then((data) => {
    console.log(data); // success promise
  })
```
>当返回值为`Promise`时，下一个回调函数将等待该`Promise`的状态发生变化，才会被调用

```javascript
const pro = new Promise(function(resolve, reject) {
  setTimeout(() => {
    resolve('success');
  }, 1000);
});
pro
  .then((data) => {
    console.log(data);
    return new Promise((resolve, reject) => {
      resolve('promise');
    });
  })
  .then((data) => {
    console.log(data); // success promise
  })
```

#### 实例方法catch
`catch`是`.then(null, rejection)、.then(undefined, rejection)`的别名，`Promise`执行发生错误的回调函数。
```javascript
const pro = new Promise(function(resolve, reject) {
  return a;
});
pro
  .catch((err) => {
    console.log(err); // ReferenceError: a is not defined
  })
```
- `then`方法运行错误也会被`catch`捕获到。所以尽量使用`catch`，避免使用`then`的处二个参数来捕获错误
```javascript
const pro = new Promise(function(resolve, reject) {
  resolve('success');
});
pro
  .then((data) => {
    return a;
  })
  .catch((err) => {
    console.log(err); // ReferenceError: a is not defined
  })
```
- 等同于抛出错误
```javascript
const pro = new Promise(function(resolve, reject) {
  throw new Error('error');
});
pro
  .catch((err) => {
    console.log(err); // Error: error
  })

const pro = new Promise(function(resolve, reject) {
  try {
    throw new Error('error');
  } catch(err) {
    reject(err);
  }
});
pro
  .catch((err) => {
    console.log(err); // Error: error
  })

const pro = new Promise(function(resolve, reject) {
  reject(new Error('error'));
});
pro
  .catch((err) => {
    console.log(err); // Error: error
  })
```
- 状态为`fulfilled`，再抛出错误将无效。因为状态确定就不会再改变
```javascript
const pro = new Promise(function(resolve, reject) {
  resolve();
  throw new Error('error');
});
pro
  .catch((err) => {
    console.log(err);
  })
```
- 不布署`catch`方法，`Promise`的错误不会传递到外层，即不会有任何反应。**建议总是布署catch方法，处理错误**
```javascript
// 浏览器会打印出错误，但是不会终止脚本运行，继续输出1
const pro = new Promise(function(resolve, reject) {
  resolve(x);
});
pro
  .then((data) => {
    console.log(data);
  })
setTimeout(() => {
  console.log(1); // 1
}, 1000)
```
- 返回一个新的`Promise`，后面还可以接着调用
```javascript
const pro = new Promise(function(resolve, reject) {
  return resolve(x);
});
pro
  .catch((err) => {
    console.log(err);
    return 'promise';
  })
  .then((data) => {
    console.log(data); // promise
  })
  ```

#### 实例方法finally
`finally`函数，无论`Promise`状态变成什么，最后都会执行它。
```javascript
const pro = new Promise(function(resolve, reject) {
  return resolve(x);
});
pro
  .then((data) => {
    console.log(data); // ReferenceError: x is not defined
  })
  .catch((err) => {
    console.log(err);
  })
  .finally(() => {
    console.log('finally'); // finally
  })
```

#### 静态方法all
`Promise.all`函数，将多个`Promise`实例包装成一个新的`Promise`实例
- **参数** 接收一个数组，数组项为`Promise`实例（非实例时会调用`Promise.resolve`转成`Promise`），非数组时，必须具有`Iterator`接口，且返回的每个成员都是`Promise`实例
```javascript
// 数组
const pro = new Promise(function(resolve, reject) {
  return resolve('success');
});
const pro1 = new Promise(function(resolve, reject) {
  return resolve('success1');
});

Promise.all([pro, pro1, 1]);
```
- **返回值**
> 所有实例状态都变成`fulfilled`时，返回值为一个数组，数组项为每个实例的返回值

```javascript
const pro = new Promise(function(resolve, reject) {
  return resolve('success');
});
const pro1 = new Promise(function(resolve, reject) {
  return resolve('success1');
});

Promise.all([pro, pro1])
  .then((data) => {
    console.log(data); // ['success', 'success1']
  });
```
> 当一个实例状态变成`rejected`时，返回值为第一个被`reject`的实例的返回值

```javascript
const pro = new Promise(function(resolve, reject) {
  return resolve('success');
});
const pro1 = new Promise(function(resolve, reject) {
  return reject('error');
});

Promise.all([pro, pro1])
  .then((data) => {
    console.log(data);
  })
  .catch((err) => {
    console.log(err); // error
  })
```
- **注意** 如果参数中的`Promise`实例布署了自己的`catch`方法，一旦状态变为`rejected`时，不会触发`Promise.all`的`catch`方法。因为**它自己处理了异常，然后返回的是一个新的`Promise`实例，且为`fulfilled`状态**
```javascript
const pro = new Promise(function(resolve, reject) {
  return resolve('success');
});
const pro1 = new Promise(function(resolve, reject) {
  return reject('error');
}).catch((e) => {
  console.log(e); // error
})

Promise.all([pro, pro1])
  .then((data) => {
    console.log(data); // ['success', undefined]
  })
  .catch((err) => {
    console.log(err);
  })
```

#### 静态方法race
`Promise.race`函数，将多个`Promise`实例包装成一个新的`Promise`实例
- **参数** 同`all`函数
- **返回值** 如果有一个实例状态改变，`race`函数即执行结束，返回值为该实例的返回值
```javascript
const pro = new Promise(function(resolve, reject) {
  return resolve('success');
});
const pro1 = new Promise(function(resolve, reject) {
  return resolve('success1');
})

Promise.race([pro, pro1])
  .then((data) => {
    console.log(data); // success
  })
```

#### 静态方法allSettled
`Promise.allSettled`函数，将多个`Promise`实例包装成一个新的`Promise`实例
- **参数** 同`all`函数
- **返回值** 所有实例状态都完成改变才会执行完毕。返回一个数组，数组项为包含`status、value或reason`键的一个对象
```javascript
const pro = new Promise(function(resolve, reject) {
  return resolve('success');
});
const pro1 = new Promise(function(resolve, reject) {
  return reject('error');
})

Promise.allSettled([pro, pro1])
  .then((data) => {
    console.log(JSON.stringify(data)); // [{"status":"fulfilled","value":"success"},{"status":"rejected","reason":"error"}]
  })
  .catch((err) => {
    console.log(err);
  })
```

#### 静态方法any
`Promise.allSettled`函数，将多个`Promise`实例包装成一个新的`Promise`实例
- **参数** 同`all`函数
- **返回值**
> 当有一个实例状态变为`fulfilled`时执行完毕，返回值为该实例的返回值

```javascript
const pro = new Promise(function(resolve, reject) {
  return resolve('success');
});
const pro1 = new Promise(function(resolve, reject) {
  return reject('error');
})

Promise.any([pro, pro1])
  .then((data) => {
    console.log(JSON.stringify(data)); // success
  })
  .catch((err) => {
    console.log(err);
  })
```
> 所有实例状态均变为rejected时，将抛出错误AggregateError: All promises were rejected

```javascript
const pro = new Promise(function(resolve, reject) {
  return reject('error1');
});
const pro1 = new Promise(function(resolve, reject) {
  return reject('error');
})

Promise.any([pro, pro1])
  .then((data) => {
    console.log(JSON.stringify(data));
  })
  .catch((err) => {
    console.log(err); // AggregateError: All promises were rejected
  })
```

#### 静态方法resolve
`Promise.resolve`函数，将普通对象转为`Promise`对象
```javascript
const jsPromise = Promise.resolve($.ajax('/whatever.json'));

Promise.resolve('foo')
// 等价于
new Promise(resolve => resolve('foo'))
```
- 参数为`Promise`实例，不做任何修改，直接返回该实例
```javascript
const pro = new Promise(function(resolve, reject) {
  return resolve('success');
});

console.log(Promise.resolve(pro)); // Promise {<fulfilled>: 'success'}
```

- 参数是一个`thenable`对象，具有`then`方法的对象。转换为`Promise`对象，然后立即执行`then`方法
```javascript
const obj = {
  then(resolve, reject) {
    resolve('success');
  }
}

Promise.resolve(obj)
  .then((data) => {
    console.log(data); // success
  })
```

- 参数为`原始值`，或是一个不带`then`方法的对象。转换为`Promise`对象，状态为`fulfilled`，并返回该值给回调函数
```javascript
Promise.resolve(1)
  .then((data) => {
    console.log(data); // 1
  });

Promise.resolve(false)
  .then((data) => {
    console.log(data); // false
  });

Promise.resolve('success')
  .then((data) => {
    console.log(data); // success
  });

Promise.resolve({})
  .then((data) => {
    console.log(data); // {}
  });

Promise.resolve(new Error('error'))
  .then((data) => {
    console.log(data); // Error: error
  });
```

- 无参数 直接返回`fulfilled`状态的`Promise`对象
```javascript
Promise.resolve()
  .then((data) => {

  });
```

- **注意** 直接返回`fulfilled`状态的`Promise`对象是在本轮**事件循环**的最后执行
```javascript
// 在下一轮事件循环开始时执行
setTimeout(function () {
  console.log('three');
}, 0);
// 在本轮事件循环结束时执行
Promise.resolve().then(function () {
  console.log('two');
});
// 同步代码立即执行
console.log('one');
// one two three
```

#### 静态方法reject
`Promise.reject`函数，返回一个新的`Promise`实例，该实例状态为`rejected`
```javascript
Promise.reject('error')
  .catch(function (err) {
    console.log(err); // error
  })
```

#### 参考
[Promise 对象](https://es6.ruanyifeng.com/#docs/promise)
